Workbook
Name AbsorptionBonusRate: Assumptions!$B$16
Name AbsorptionRate: 'Service & Parts'!$B$227
Name AgedInventoryMultiplier: Assumptions!$B$30
Name AvgDaysOnLot_UV: Assumptions!$B$29
Name CommissionTable: Assumptions!$A$35:$E$38
Name Deal_Count_Range: 'F&I Detail'!$B$4:$B$153
Name EffectiveFloorPlanRate: Assumptions!$B$28
Name FI_Cost_Range: 'F&I Detail'!$F$4:$F$153
Name FI_Month_Range: 'F&I Detail'!$D$4:$D$153
Name FI_Net_Range: 'F&I Detail'!$J$4:$J$153
Name FI_PVR_Target: Assumptions!$B$8
Name FI_Revenue_Range: 'F&I Detail'!$G$4:$G$153
Name FloorPlanRate: Assumptions!$B$4
Name FloorPlanSpread: Assumptions!$B$27
Name HoldbackRate: Assumptions!$B$11
Name IncentiveRate_Ford: Assumptions!$B$7
Name IncentiveRate_Honda: Assumptions!$B$6
Name IncentiveRate_Toyota: Assumptions!$B$5
Name NV_Bonus: 'New Vehicle'!$P$4:$P$53
Name NV_Commission: 'New Vehicle'!$O$4:$O$53
Name NV_FI: 'New Vehicle'!$K$4:$K$53
Name NV_FrontGross: 'New Vehicle'!$J$4:$J$53
Name NV_HPI: 'New Vehicle'!$Q$4:$Q$53
Name NV_Month: 'New Vehicle'!$D$4:$D$53
Name NV_Stock: 'New Vehicle'!$A$4:$A$53
Name NV_Tier: 'New Vehicle'!$N$4:$N$53
Name NV_TotalComp: 'New Vehicle'!$R$4:$R$53
Name PartsGross: 'Service & Parts'!$B$225
Name PrimeRate: Assumptions!$B$26
Name PVR_Target: Assumptions!$B$8
Name ReconCostCap: Assumptions!$B$12
Name RiskAdjustedFloorPlanRate: Assumptions!$B$31
Name ServiceAbsorptionTarget: Assumptions!$B$9
Name SV_LaborCost: 'Service & Parts'!$F$4:$F$203
Name SV_LaborRev: 'Service & Parts'!$E$4:$E$203
Name SV_Month: 'Service & Parts'!$C$4:$C$203
Name SV_PartsCost: 'Service & Parts'!$H$4:$H$203
Name SV_PartsRev: 'Service & Parts'!$G$4:$G$203
Name SV_TotGross: 'Service & Parts'!$J$4:$J$203
Name SV_TotRev: 'Service & Parts'!$I$4:$I$203
Name SV_Type: 'Service & Parts'!$D$4:$D$203
Name SvcGross: 'Service & Parts'!$B$224
Name TaxRate: Assumptions!$B$10
Name TierMinPVR_Gold: Assumptions!$B$37
Name TierMinPVR_Platinum: Assumptions!$B$38
Name TierMinPVR_Silver: Assumptions!$B$36
Name UV_AdjGross: 'Used Vehicle'!$L$4:$L$53
Name UV_FI: 'Used Vehicle'!$K$4:$K$53
Name UV_Month: 'Used Vehicle'!$D$4:$D$53
Name UV_SalePrice: 'Used Vehicle'!$G$4:$G$53
Name UV_Stock: 'Used Vehicle'!$A$4:$A$53
Name UV_TotGross: 'Used Vehicle'!$M$4:$M$53
Name VarianceThreshold: Assumptions!$B$14

Sheet P&L Summary
A1: PROFIT & LOSS SUMMARY — FY2025
A3: Line Item | B3: Jan | C3: Feb | D3: Mar | E3: Apr | F3: May | G3: Jun | H3: Jul | I3: Aug | J3: Sep | K3: Oct | L3: Nov | M3: Dec | N3: YTD | O3: Budget | P3: Variance %
A4: New Vehicle Sales | B4: =SUMIFS('New Vehicle'!$F$4:$F$53,NV_Month,"Jan") -> 140718 | C4: =SUMIFS('New Vehicle'!$F$4:$F$53,NV_Month,"Feb") -> 171851 | D4: =SUMIFS('New Vehicle'!$F$4:$F$53,NV_Month,"Mar") -> 137916 | E4: =SUMIFS('New Vehicle'!$F$4:$F$53,NV_Month,"Apr") -> 221224 | F4: =SUMIFS('New Vehicle'!$F$4:$F$53,NV_Month,"May") -> 134048 | G4: =SUMIFS('New Vehicle'!$F$4:$F$53,NV_Month,"Jun") -> 296551 | H4: =SUMIFS('New Vehicle'!$F$4:$F$53,NV_Month,"Jul") -> 146264 | I4: =SUMIFS('New Vehicle'!$F$4:$F$53,NV_Month,"Aug") -> 81490 | J4: =SUMIFS('New Vehicle'!$F$4:$F$53,NV_Month,"Sep") -> 224689 | K4: =SUMIFS('New Vehicle'!$F$4:$F$53,NV_Month,"Oct") -> 152975 | L4: =SUMIFS('New Vehicle'!$F$4:$F$53,NV_Month,"Nov") -> 358202 | M4: =SUMIFS('New Vehicle'!$F$4:$F$53,NV_Month,"Dec") -> 65840 | N4: =SUM(B4:M4) -> 2131768 | O4: 26400000 | P4: =IFERROR((N4-O4)/O4,0) -> -0.91925121
A5: Used Vehicle Sales | B5: =SUMIFS(UV_SalePrice,UV_Month,"Jan") -> 191388 | C5: =SUMIFS(UV_SalePrice,UV_Month,"Feb") -> 135413 | D5: =SUMIFS(UV_SalePrice,UV_Month,"Mar") -> 48495 | E5: =SUMIFS(UV_SalePrice,UV_Month,"Apr") -> 232006 | F5: =SUMIFS(UV_SalePrice,UV_Month,"May") -> 138771 | G5: =SUMIFS(UV_SalePrice,UV_Month,"Jun") -> 60321 | H5: =SUMIFS(UV_SalePrice,UV_Month,"Jul") -> 135241 | I5: =SUMIFS(UV_SalePrice,UV_Month,"Aug") -> 64884 | J5: =SUMIFS(UV_SalePrice,UV_Month,"Sep") -> 35598 | K5: =SUMIFS(UV_SalePrice,UV_Month,"Oct") -> 74899 | L5: =SUMIFS(UV_SalePrice,UV_Month,"Nov") -> 201306 | M5: =SUMIFS(UV_SalePrice,UV_Month,"Dec") -> 49781 | N5: =SUM(B5:M5) -> 1368103 | O5: 13200000 | P5: =IFERROR((N5-O5)/O5,0) -> -0.89635583
A6: F&I Income | B6: =SUMIFS(FI_Net_Range,FI_Month_Range,"Jan") -> 15810 | C6: =SUMIFS(FI_Net_Range,FI_Month_Range,"Feb") -> 10467 | D6: =SUMIFS(FI_Net_Range,FI_Month_Range,"Mar") -> 5503 | E6: =SUMIFS(FI_Net_Range,FI_Month_Range,"Apr") -> 23206 | F6: =SUMIFS(FI_Net_Range,FI_Month_Range,"May") -> 15493 | G6: =SUMIFS(FI_Net_Range,FI_Month_Range,"Jun") -> 17787 | H6: =SUMIFS(FI_Net_Range,FI_Month_Range,"Jul") -> 12583 | I6: =SUMIFS(FI_Net_Range,FI_Month_Range,"Aug") -> 5448 | J6: =SUMIFS(FI_Net_Range,FI_Month_Range,"Sep") -> 14403 | K6: =SUMIFS(FI_Net_Range,FI_Month_Range,"Oct") -> 15411 | L6: =SUMIFS(FI_Net_Range,FI_Month_Range,"Nov") -> 35653 | M6: =SUMIFS(FI_Net_Range,FI_Month_Range,"Dec") -> 7160 | N6: =SUM(B6:M6) -> 178924 | O6: 3000000 | P6: =IFERROR((N6-O6)/O6,0) -> -0.94035867
A7: Service Revenue | B7: =SUMIFS(SV_LaborRev,SV_Month,"Jan") -> 3096 | C7: =SUMIFS(SV_LaborRev,SV_Month,"Feb") -> 9095 | D7: =SUMIFS(SV_LaborRev,SV_Month,"Mar") -> 4238 | E7: =SUMIFS(SV_LaborRev,SV_Month,"Apr") -> 5704 | F7: =SUMIFS(SV_LaborRev,SV_Month,"May") -> 5994 | G7: =SUMIFS(SV_LaborRev,SV_Month,"Jun") -> 8502 | H7: =SUMIFS(SV_LaborRev,SV_Month,"Jul") -> 7154 | I7: =SUMIFS(SV_LaborRev,SV_Month,"Aug") -> 4760 | J7: =SUMIFS(SV_LaborRev,SV_Month,"Sep") -> 8305 | K7: =SUMIFS(SV_LaborRev,SV_Month,"Oct") -> 6682 | L7: =SUMIFS(SV_LaborRev,SV_Month,"Nov") -> 6570 | M7: =SUMIFS(SV_LaborRev,SV_Month,"Dec") -> 8373 | N7: =SUM(B7:M7) -> 78473 | O7: 4200000 | P7: =IFERROR((N7-O7)/O7,0) -> -0.98131595
A8: Parts Revenue | B8: =SUMIFS(SV_PartsRev,SV_Month,"Jan") -> 3148 | C8: =SUMIFS(SV_PartsRev,SV_Month,"Feb") -> 5641 | D8: =SUMIFS(SV_PartsRev,SV_Month,"Mar") -> 2584 | E8: =SUMIFS(SV_PartsRev,SV_Month,"Apr") -> 4414 | F8: =SUMIFS(SV_PartsRev,SV_Month,"May") -> 3426 | G8: =SUMIFS(SV_PartsRev,SV_Month,"Jun") -> 6884 | H8: =SUMIFS(SV_PartsRev,SV_Month,"Jul") -> 5016 | I8: =SUMIFS(SV_PartsRev,SV_Month,"Aug") -> 2405 | J8: =SUMIFS(SV_PartsRev,SV_Month,"Sep") -> 6079 | K8: =SUMIFS(SV_PartsRev,SV_Month,"Oct") -> 4856 | L8: =SUMIFS(SV_PartsRev,SV_Month,"Nov") -> 6142 | M8: =SUMIFS(SV_PartsRev,SV_Month,"Dec") -> 7283 | N8: =SUM(B8:M8) -> 57878 | O8: 3000000 | P8: =IFERROR((N8-O8)/O8,0) -> -0.98070733
A9: Body Shop Revenue | B9: =B7*0.45 -> 1393.2 | C9: =C7*0.45 -> 4092.75 | D9: =D7*0.45 -> 1907.1 | E9: =E7*0.45 -> 2566.8 | F9: =F7*0.45 -> 2697.3 | G9: =G7*0.45 -> 3825.9 | H9: =H7*0.45 -> 3219.3 | I9: =I7*0.45 -> 2142 | ... M9: =M7*0.45 -> 3767.85 | N9: =SUM(B9:M9) -> 35312.85 | O9: 1800000 | P9: =IFERROR((N9-O9)/O9,0) -> -0.98038175
A10: TOTAL REVENUE | B10: =SUM(B4:B9) -> 355553.2 | C10: =SUM(C4:C9) -> 336559.75 | D10: =SUM(D4:D9) -> 200643.1 | E10: =SUM(E4:E9) -> 489120.8 | F10: =SUM(F4:F9) -> 300429.3 | G10: =SUM(G4:G9) -> 393870.9 | H10: =SUM(H4:H9) -> 309477.3 | I10: =SUM(I4:I9) -> 161129 | ... M10: =SUM(M4:M9) -> 142204.85 | N10: =SUM(B10:M10) -> 3850458.8 | O10: =SUM(O4:O9) -> 51600000 | P10: =IFERROR((N10-O10)/O10,0) -> -0.9253787
A12: GROSS PROFIT BY DEPARTMENT
A13: New Vehicle Gross | B13: =SUMIFS(NV_FrontGross,NV_Month,"Jan") -> 19533.288 | C13: =SUMIFS(NV_FrontGross,NV_Month,"Feb") -> 23133.986 | D13: =SUMIFS(NV_FrontGross,NV_Month,"Mar") -> 15878.412 | E13: =SUMIFS(NV_FrontGross,NV_Month,"Apr") -> 29644.458 | F13: =SUMIFS(NV_FrontGross,NV_Month,"May") -> 16959.896 | G13: =SUMIFS(NV_FrontGross,NV_Month,"Jun") -> 42096.898 | H13: =SUMIFS(NV_FrontGross,NV_Month,"Jul") -> 20344.018 | I13: =SUMIFS(NV_FrontGross,NV_Month,"Aug") -> 10546.609 | J13: =SUMIFS(NV_FrontGross,NV_Month,"Sep") -> 27252.64 | K13: =SUMIFS(NV_FrontGross,NV_Month,"Oct") -> 21054.926 | L13: =SUMIFS(NV_FrontGross,NV_Month,"Nov") -> 46756.888 | M13: =SUMIFS(NV_FrontGross,NV_Month,"Dec") -> 9483.014 | N13: =SUM(B13:M13) -> 282685.03
A14: Used Vehicle Gross | B14: =SUMIFS(UV_AdjGross,UV_Month,"Jan") -> 29369.724 | C14: =SUMIFS(UV_AdjGross,UV_Month,"Feb") -> 25965.147 | D14: =SUMIFS(UV_AdjGross,UV_Month,"Mar") -> 8216.5543 | E14: =SUMIFS(UV_AdjGross,UV_Month,"Apr") -> 40198.998 | F14: =SUMIFS(UV_AdjGross,UV_Month,"May") -> 19803.285 | G14: =SUMIFS(UV_AdjGross,UV_Month,"Jun") -> 14378.615 | H14: =SUMIFS(UV_AdjGross,UV_Month,"Jul") -> 25049.908 | I14: =SUMIFS(UV_AdjGross,UV_Month,"Aug") -> 13624.264 | J14: =SUMIFS(UV_AdjGross,UV_Month,"Sep") -> 6857.3847 | K14: =SUMIFS(UV_AdjGross,UV_Month,"Oct") -> 14607.421 | L14: =SUMIFS(UV_AdjGross,UV_Month,"Nov") -> 29895.768 | M14: =SUMIFS(UV_AdjGross,UV_Month,"Dec") -> 6498.9282 | N14: =SUM(B14:M14) -> 234466
A15: F&I Gross | B15: =SUMIFS(FI_Net_Range,FI_Month_Range,"Jan") -> 15810 | C15: =SUMIFS(FI_Net_Range,FI_Month_Range,"Feb") -> 10467 | D15: =SUMIFS(FI_Net_Range,FI_Month_Range,"Mar") -> 5503 | E15: =SUMIFS(FI_Net_Range,FI_Month_Range,"Apr") -> 23206 | F15: =SUMIFS(FI_Net_Range,FI_Month_Range,"May") -> 15493 | G15: =SUMIFS(FI_Net_Range,FI_Month_Range,"Jun") -> 17787 | H15: =SUMIFS(FI_Net_Range,FI_Month_Range,"Jul") -> 12583 | I15: =SUMIFS(FI_Net_Range,FI_Month_Range,"Aug") -> 5448 | J15: =SUMIFS(FI_Net_Range,FI_Month_Range,"Sep") -> 14403 | K15: =SUMIFS(FI_Net_Range,FI_Month_Range,"Oct") -> 15411 | L15: =SUMIFS(FI_Net_Range,FI_Month_Range,"Nov") -> 35653 | M15: =SUMIFS(FI_Net_Range,FI_Month_Range,"Dec") -> 7160 | N15: =SUM(B15:M15) -> 178924
A16: Service & Parts Gross | B16: =SUMIFS(SV_TotGross,SV_Month,"Jan") -> 3090 | C16: =SUMIFS(SV_TotGross,SV_Month,"Feb") -> 7516 | D16: =SUMIFS(SV_TotGross,SV_Month,"Mar") -> 3491 | E16: =SUMIFS(SV_TotGross,SV_Month,"Apr") -> 4997 | F16: =SUMIFS(SV_TotGross,SV_Month,"May") -> 5087 | G16: =SUMIFS(SV_TotGross,SV_Month,"Jun") -> 7779 | H16: =SUMIFS(SV_TotGross,SV_Month,"Jul") -> 5980 | I16: =SUMIFS(SV_TotGross,SV_Month,"Aug") -> 3677 | J16: =SUMIFS(SV_TotGross,SV_Month,"Sep") -> 7264 | K16: =SUMIFS(SV_TotGross,SV_Month,"Oct") -> 5711 | L16: =SUMIFS(SV_TotGross,SV_Month,"Nov") -> 6363 | M16: =SUMIFS(SV_TotGross,SV_Month,"Dec") -> 7786 | N16: =SUM(B16:M16) -> 68741
A17: Body Shop Gross | B17: =B9*0.5 -> 696.6 | C17: =C9*0.5 -> 2046.375 | D17: =D9*0.5 -> 953.55 | E17: =E9*0.5 -> 1283.4 | F17: =F9*0.5 -> 1348.65 | G17: =G9*0.5 -> 1912.95 | H17: =H9*0.5 -> 1609.65 | I17: =I9*0.5 -> 1071 | ... M17: =M9*0.5 -> 1883.925 | N17: =SUM(B17:M17) -> 17656.425
A18: TOTAL GROSS PROFIT | B18: =SUM(B13:B17) -> 68499.612 | C18: =SUM(C13:C17) -> 69128.508 | D18: =SUM(D13:D17) -> 34042.516 | E18: =SUM(E13:E17) -> 99329.856 | F18: =SUM(F13:F17) -> 58691.831 | G18: =SUM(G13:G17) -> 83954.463 | H18: =SUM(H13:H17) -> 65566.576 | I18: =SUM(I13:I17) -> 34366.873 | ... M18: =SUM(M13:M17) -> 32811.867 | N18: =SUM(B18:M18) -> 782472.46 | O18: =O10*0.15 -> 7740000 | P18: =IFERROR((N18-O18)/O18,0) -> -0.89890537
A19: Gross Margin % | B19: =IFERROR(B18/B10,0) -> 0.19265644 | C19: =IFERROR(C18/C10,0) -> 0.20539743 | D19: =IFERROR(D18/D10,0) -> 0.16966702 | E19: =IFERROR(E18/E10,0) -> 0.20307837 | F19: =IFERROR(F18/F10,0) -> 0.19535988 | G19: =IFERROR(G18/G10,0) -> 0.21315224 | H19: =IFERROR(H18/H10,0) -> 0.21186231 | I19: =IFERROR(I18/I10,0) -> 0.21328794 | ... N19: =IFERROR(N18/N10,0) -> 0.20321538
A21: OPERATING EXPENSES
A22: Personnel | B22: =SUMIFS(NV_TotalComp,NV_Month,"Jan")+B10*0.05 -> 18544.272 | C22: =SUMIFS(NV_TotalComp,NV_Month,"Feb")+C10*0.05 -> 17806.567 | D22: =SUMIFS(NV_TotalComp,NV_Month,"Mar")+D10*0.05 -> 10826.076 | E22: =SUMIFS(NV_TotalComp,NV_Month,"Apr")+E10*0.05 -> 26086.485 | F22: =SUMIFS(NV_TotalComp,NV_Month,"May")+F10*0.05 -> 15737.231 | G22: =SUMIFS(NV_TotalComp,NV_Month,"Jun")+G10*0.05 -> 22385.799 | H22: =SUMIFS(NV_TotalComp,NV_Month,"Jul")+H10*0.05 -> 16756.445 | I22: =SUMIFS(NV_TotalComp,NV_Month,"Aug")+I10*0.05 -> 8267.3822 | J22: =SUMIFS(NV_TotalComp,NV_Month,"Sep")+J10*0.05 -> 16067.19 | K22: =SUMIFS(NV_TotalComp,NV_Month,"Oct")+K10*0.05 -> 13455.899 | L22: =SUMIFS(NV_TotalComp,NV_Month,"Nov")+L10*0.05 -> 33137.695 | M22: =SUMIFS(NV_TotalComp,NV_Month,"Dec")+M10*0.05 -> 7299.9028 | N22: =SUM(B22:M22) -> 206370.94
A23: Advertising | B23: =B10*0.012 -> 4266.6384 | C23: =C10*0.012 -> 4038.717 | D23: =D10*0.012 -> 2407.7172 | E23: =E10*0.012 -> 5869.4496 | F23: =F10*0.012 -> 3605.1516 | G23: =G10*0.012 -> 4726.4508 | H23: =H10*0.012 -> 3713.7276 | I23: =I10*0.012 -> 1933.548 | ... M23: =M10*0.012 -> 1706.4582 | N23: =SUM(B23:M23) -> 46205.506
A24: Facilities | B24: =B10*0.015 -> 5333.298 | C24: =C10*0.015 -> 5048.3962 | D24: =D10*0.015 -> 3009.6465 | E24: =E10*0.015 -> 7336.812 | F24: =F10*0.015 -> 4506.4395 | G24: =G10*0.015 -> 5908.0635 | H24: =H10*0.015 -> 4642.1595 | I24: =I10*0.015 -> 2416.935 | ... M24: =M10*0.015 -> 2133.0727 | N24: =SUM(B24:M24) -> 57756.883
A25: TOTAL OPERATING EXPENSES | B25: =SUM(B22:B24) -> 28144.209 | C25: =SUM(C22:C24) -> 26893.68 | D25: =SUM(D22:D24) -> 16243.439 | E25: =SUM(E22:E24) -> 39292.747 | F25: =SUM(F22:F24) -> 23848.822 | G25: =SUM(G22:G24) -> 33020.313 | H25: =SUM(H22:H24) -> 25112.332 | I25: =SUM(I22:I24) -> 12617.865 | ... M25: =SUM(M22:M24) -> 11139.434 | N25: =SUM(B25:M25) -> 310333.33
A27: OPERATING INCOME | B27: =B18-B25 -> 40355.404 | C27: =C18-C25 -> 42234.828 | D27: =D18-D25 -> 17799.077 | E27: =E18-E25 -> 60037.109 | F27: =F18-F25 -> 34843.009 | G27: =G18-G25 -> 50934.15 | H27: =H18-H25 -> 40454.243 | I27: =I18-I25 -> 21749.008 | ... M27: =M18-M25 -> 21672.433 | N27: =SUM(B27:M27) -> 472139.12
A29: ADDBACKS
A30: Depreciation & Amortization | B30: =B10*0.02 -> 7111.064 | C30: =C10*0.02 -> 6731.195 | D30: =D10*0.02 -> 4012.862 | E30: =E10*0.02 -> 9782.416 | F30: =F10*0.02 -> 6008.586 | G30: =G10*0.02 -> 7877.418 | H30: =H10*0.02 -> 6189.546 | I30: =I10*0.02 -> 3222.58 | ... M30: =M10*0.02 -> 2844.097 | N30: =SUM(B30:M30) -> 77009.177
A31: Absorption Bonus Addback | B31: =IF(AbsorptionRate>ServiceAbsorptionTarget,(AbsorptionRate-ServiceAbsorptionTarget)*B10*AbsorptionBonusRate,0) -> 0 | C31: =IF(AbsorptionRate>ServiceAbsorptionTarget,(AbsorptionRate-ServiceAbsorptionTarget)*C10*AbsorptionBonusRate,0) -> 0 | D31: =IF(AbsorptionRate>ServiceAbsorptionTarget,(AbsorptionRate-ServiceAbsorptionTarget)*D10*AbsorptionBonusRate,0) -> 0 | E31: =IF(AbsorptionRate>ServiceAbsorptionTarget,(AbsorptionRate-ServiceAbsorptionTarget)*E10*AbsorptionBonusRate,0) -> 0 | F31: =IF(AbsorptionRate>ServiceAbsorptionTarget,(AbsorptionRate-ServiceAbsorptionTarget)*F10*AbsorptionBonusRate,0) -> 0 | G31: =IF(AbsorptionRate>ServiceAbsorptionTarget,(AbsorptionRate-ServiceAbsorptionTarget)*G10*AbsorptionBonusRate,0) -> 0 | H31: =IF(AbsorptionRate>ServiceAbsorptionTarget,(AbsorptionRate-ServiceAbsorptionTarget)*H10*AbsorptionBonusRate,0) -> 0 | I31: =IF(AbsorptionRate>ServiceAbsorptionTarget,(AbsorptionRate-ServiceAbsorptionTarget)*I10*AbsorptionBonusRate,0) -> 0 | ... M31: =IF(AbsorptionRate>ServiceAbsorptionTarget,(AbsorptionRate-ServiceAbsorptionTarget)*M10*AbsorptionBonusRate,0) -> 0 | N31: =SUM(B31:M31) -> 0
A32: ADJUSTED EBITDA | B32: =B18-B25+B30+B31 -> 47466.468 | C32: =C18-C25+C30+C31 -> 48966.023 | D32: =D18-D25+D30+D31 -> 21811.939 | E32: =E18-E25+E30+E31 -> 69819.525 | F32: =F18-F25+F30+F31 -> 40851.595 | G32: =G18-G25+G30+G31 -> 58811.568 | H32: =H18-H25+H30+H31 -> 46643.789 | I32: =I18-I25+I30+I31 -> 24971.588 | ... M32: =M18-M25+M30+M31 -> 24516.53 | N32: =SUM(B32:M32) -> 549148.3 | O32: =O10*0.065 -> 3354000 | P32: =IFERROR((N32-O32)/O32,0) -> -0.83627063
A33: EBITDA Margin | B33: =IFERROR(B32/B10,0) -> 0.13350032 | C33: =IFERROR(C32/C10,0) -> 0.14548984 | D33: =IFERROR(D32/D10,0) -> 0.10871014 | E33: =IFERROR(E32/E10,0) -> 0.14274495 | F33: =IFERROR(F32/F10,0) -> 0.1359774 | G33: =IFERROR(G32/G10,0) -> 0.14931686 | H33: =IFERROR(H32/H10,0) -> 0.15071797 | I33: =IFERROR(I32/I10,0) -> 0.15497886 | ... N33: =IFERROR(N32/N10,0) -> 0.14261892
A34: Tax Provision | B34: =MAX(B32*TaxRate,0) -> 9967.9582 | C34: =MAX(C32*TaxRate,0) -> 10282.865 | D34: =MAX(D32*TaxRate,0) -> 4580.5072 | E34: =MAX(E32*TaxRate,0) -> 14662.1 | F34: =MAX(F32*TaxRate,0) -> 8578.8349 | G34: =MAX(G32*TaxRate,0) -> 12350.429 | H34: =MAX(H32*TaxRate,0) -> 9795.1958 | I34: =MAX(I32*TaxRate,0) -> 5244.0335 | ... M34: =MAX(M32*TaxRate,0) -> 5148.4714 | N34: =SUM(B34:M34) -> 115321.14
A35: NET INCOME | B35: =B32-B34 -> 37498.509 | C35: =C32-C34 -> 38683.158 | D35: =D32-D34 -> 17231.432 | E35: =E32-E34 -> 55157.425 | F35: =F32-F34 -> 32272.76 | G35: =G32-G34 -> 46461.139 | H35: =H32-H34 -> 36848.594 | I35: =I32-I34 -> 19727.555 | ... M35: =M32-M34 -> 19368.059 | N35: =SUM(B35:M35) -> 433827.16 | O35: =O32*(1-TaxRate) -> 2649660 | P35: =IFERROR((N35-O35)/O35,0) -> -0.83627063
A38: ▼ DEEP FORMULA CHAIN SHOWCASE ▼
A39: Chain Step | B39: Description | C39: Value | D39: Formula Anatomy
A40: Hop 1 (Leaf) | B40: PrimeRate (input) | C40: =PrimeRate -> 0.055 | D40: Hardcoded on Assumptions!B26
A41: Hop 2 | B41: EffectiveFloorPlanRate = Prime + Spread | C41: =EffectiveFloorPlanRate -> 0.0635 | D41: =B26+B27 on Assumptions -> #NAME?
A42: Hop 3 | B42: AvgDaysOnLot (cross-sheet AVERAGE) | C42: =AvgDaysOnLot_UV -> 55.92 | D42: =AVERAGE('Used Vehicle'!F4:F53) -> 55.92
A43: Hop 4 | B43: AgedInventoryMultiplier (IF tier) | C43: =AgedInventoryMultiplier -> 1.15 | D43: =IF(B29>60,1.25,IF(B29>45,1.15,1)) -> 1
A44: Hop 5 | B44: RiskAdjustedFloorPlanRate = Eff × Aged | C44: =RiskAdjustedFloorPlanRate -> 0.073025
A45: Hop 6 | B45: Total Floor Plan Interest (UV sheet) | C45: =SUMPRODUCT('Used Vehicle'!F4:F53,'Used Vehicle'!H4:H53)*RiskAdjustedFloorPlanRate/365 -> 12285.002 | D45: SUMPRODUCT of DOL×Cost × rate
A46: Hop 7 (Aggregate) | B46: Used Adjusted Gross (feeds P&L row 14) | C46: =SUM(UV_AdjGross) -> 234466 | D46: =SalePrice - Cost - Recon - FloorPlanInt -> #NAME?
A47: Hop 8 (Consumer) | B47: Total Gross Profit YTD (row 18 N col) | C47: =N18 -> 782472.46
...

Sheet New Vehicle
A1: NEW VEHICLE DEAL LOG
A3: Stock# | B3: VIN | C3: Sale Date | D3: Month | E3: OEM | F3: Sale Price | G3: Invoice Cost | H3: Holdback | I3: Incentive Allocation | J3: Front Gross | K3: F&I Revenue | L3: Total Deal Gross | M3: Deal PVR | N3: Performance Tier | O3: Base Commission | P3: Tier Bonus | Q3: High-Performer Incentive | R3: Total Compensation
A4: N1017 | B4: VINT100017 | C4: 45665 | D4: =TEXT(C4,"mmm") -> Jan | E4: Toyota | F4: 54379 | G4: 48882 | H4: =G4*HoldbackRate -> 1222.05 | I4: =G4*IF(E4="Toyota",IncentiveRate_Toyota,IF(E4="Honda",IncentiveRate_Honda,IF(E4="Ford",IncentiveRate_Ford,0))) -> 1026.522 | J4: =F4-G4+H4+I4 -> 7745.572 | K4: 1348 | L4: =J4+K4 -> 9093.572 | M4: =K4 -> 1348 | N4: =IF(M4>=TierMinPVR_Platinum,"Platinum",IF(M4>=TierMinPVR_Gold,"Gold",IF(M4>=TierMinPVR_Silver,"Silver","Bronze"))) -> Silver | O4: =J4*VLOOKUP(N4,CommissionTable,3,FALSE) -> 232.36716 | P4: =IF(O4>VLOOKUP(N4,CommissionTable,5,FALSE),J4*VLOOKUP(N4,CommissionTable,4,FALSE),0) -> 77.45572 | Q4: =IF(VLOOKUP(N4,CommissionTable,3,FALSE)>0.03,SUMIFS($J$4:$J$53,$D$4:$D$53,D4,$C$4:$C$53,">"&DATE(2025,1,1))*0.005,0) -> 0 | R4: =O4+P4+Q4 -> 309.82288
A5: N1011 | B5: VINT100011 | C5: 45679 | D5: =TEXT(C5,"mmm") -> Jan | E5: Toyota | F5: 53331 | G5: 47857 | H5: =G5*HoldbackRate -> 1196.425 | I5: =G5*IF(E5="Toyota",IncentiveRate_Toyota,IF(E5="Honda",IncentiveRate_Honda,IF(E5="Ford",IncentiveRate_Ford,0))) -> 1004.997 | J5: =F5-G5+H5+I5 -> 7675.422 | K5: 963 | L5: =J5+K5 -> 8638.422 | M5: =K5 -> 963 | N5: =IF(M5>=TierMinPVR_Platinum,"Platinum",IF(M5>=TierMinPVR_Gold,"Gold",IF(M5>=TierMinPVR_Silver,"Silver","Bronze"))) -> Bronze | O5: =J5*VLOOKUP(N5,CommissionTable,3,FALSE) -> 153.50844 | P5: =IF(O5>VLOOKUP(N5,CommissionTable,5,FALSE),J5*VLOOKUP(N5,CommissionTable,4,FALSE),0) -> 0 | Q5: =IF(VLOOKUP(N5,CommissionTable,3,FALSE)>0.03,SUMIFS($J$4:$J$53,$D$4:$D$53,D5,$C$4:$C$53,">"&DATE(2025,1,1))*0.005,0) -> 0 | R5: =O5+P5+Q5 -> 153.50844
A6: N1023 | B6: VINT100023 | C6: 45685 | D6: =TEXT(C6,"mmm") -> Jan | E6: Toyota | F6: 33008 | G6: 30289 | H6: =G6*HoldbackRate -> 757.225 | I6: =G6*IF(E6="Toyota",IncentiveRate_Toyota,IF(E6="Honda",IncentiveRate_Honda,IF(E6="Ford",IncentiveRate_Ford,0))) -> 636.069 | J6: =F6-G6+H6+I6 -> 4112.294 | K6: 2422 | L6: =J6+K6 -> 6534.294 | M6: =K6 -> 2422 | N6: =IF(M6>=TierMinPVR_Platinum,"Platinum",IF(M6>=TierMinPVR_Gold,"Gold",IF(M6>=TierMinPVR_Silver,"Silver","Bronze"))) -> Platinum | O6: =J6*VLOOKUP(N6,CommissionTable,3,FALSE) -> 205.6147 | P6: =IF(O6>VLOOKUP(N6,CommissionTable,5,FALSE),J6*VLOOKUP(N6,CommissionTable,4,FALSE),0) -> 0 | Q6: =IF(VLOOKUP(N6,CommissionTable,3,FALSE)>0.03,SUMIFS($J$4:$J$53,$D$4:$D$53,D6,$C$4:$C$53,">"&DATE(2025,1,1))*0.005,0) -> 97.66644 | R6: =O6+P6+Q6 -> 303.28114
A7: N1047 | B7: VINH100047 | C7: 45690 | D7: =TEXT(C7,"mmm") -> Feb | E7: Honda | F7: 51862 | G7: 46694 | H7: =G7*HoldbackRate -> 1167.35 | I7: =G7*IF(E7="Toyota",IncentiveRate_Toyota,IF(E7="Honda",IncentiveRate_Honda,IF(E7="Ford",IncentiveRate_Ford,0))) -> 840.492 | J7: =F7-G7+H7+I7 -> 7175.842 | K7: 2564 | L7: =J7+K7 -> 9739.842 | M7: =K7 -> 2564 | N7: =IF(M7>=TierMinPVR_Platinum,"Platinum",IF(M7>=TierMinPVR_Gold,"Gold",IF(M7>=TierMinPVR_Silver,"Silver","Bronze"))) -> Platinum | O7: =J7*VLOOKUP(N7,CommissionTable,3,FALSE) -> 358.7921 | P7: =IF(O7>VLOOKUP(N7,CommissionTable,5,FALSE),J7*VLOOKUP(N7,CommissionTable,4,FALSE),0) -> 0 | Q7: =IF(VLOOKUP(N7,CommissionTable,3,FALSE)>0.03,SUMIFS($J$4:$J$53,$D$4:$D$53,D7,$C$4:$C$53,">"&DATE(2025,1,1))*0.005,0) -> 115.66993 | R7: =O7+P7+Q7 -> 474.46203
A8: N1018 | B8: VINF100018 | C8: 45695 | D8: =TEXT(C8,"mmm") -> Feb | E8: Ford | F8: 56716 | G8: 52353 | H8: =G8*HoldbackRate -> 1308.825 | I8: =G8*IF(E8="Toyota",IncentiveRate_Toyota,IF(E8="Honda",IncentiveRate_Honda,IF(E8="Ford",IncentiveRate_Ford,0))) -> 1308.825 | J8: =F8-G8+H8+I8 -> 6980.65 | K8: 1235 | L8: =J8+K8 -> 8215.65 | M8: =K8 -> 1235 | N8: =IF(M8>=TierMinPVR_Platinum,"Platinum",IF(M8>=TierMinPVR_Gold,"Gold",IF(M8>=TierMinPVR_Silver,"Silver","Bronze"))) -> Silver | O8: =J8*VLOOKUP(N8,CommissionTable,3,FALSE) -> 209.4195 | P8: =IF(O8>VLOOKUP(N8,CommissionTable,5,FALSE),J8*VLOOKUP(N8,CommissionTable,4,FALSE),0) -> 69.8065 | Q8: =IF(VLOOKUP(N8,CommissionTable,3,FALSE)>0.03,SUMIFS($J$4:$J$53,$D$4:$D$53,D8,$C$4:$C$53,">"&DATE(2025,1,1))*0.005,0) -> 0 | R8: =O8+P8+Q8 -> 279.226
A9: N1048 | B9: VINT100048 | C9: 45696 | D9: =TEXT(C9,"mmm") -> Feb | E9: Toyota | F9: 34232 | G9: 31225 | H9: =G9*HoldbackRate -> 780.625 | I9: =G9*IF(E9="Toyota",IncentiveRate_Toyota,IF(E9="Honda",IncentiveRate_Honda,IF(E9="Ford",IncentiveRate_Ford,0))) -> 655.725 | J9: =F9-G9+H9+I9 -> 4443.35 | K9: 1087 | L9: =J9+K9 -> 5530.35 | M9: =K9 -> 1087 | N9: =IF(M9>=TierMinPVR_Platinum,"Platinum",IF(M9>=TierMinPVR_Gold,"Gold",IF(M9>=TierMinPVR_Silver,"Silver","Bronze"))) -> Bronze | O9: =J9*VLOOKUP(N9,CommissionTable,3,FALSE) -> 88.867 | P9: =IF(O9>VLOOKUP(N9,CommissionTable,5,FALSE),J9*VLOOKUP(N9,CommissionTable,4,FALSE),0) -> 0 | Q9: =IF(VLOOKUP(N9,CommissionTable,3,FALSE)>0.03,SUMIFS($J$4:$J$53,$D$4:$D$53,D9,$C$4:$C$53,">"&DATE(2025,1,1))*0.005,0) -> 0 | R9: =O9+P9+Q9 -> 88.867
A10: N1002 | B10: VINH100002 | C10: 45707 | D10: =TEXT(C10,"mmm") -> Feb | E10: Honda | F10: 29041 | G10: 25608 | H10: =G10*HoldbackRate -> 640.2 | I10: =G10*IF(E10="Toyota",IncentiveRate_Toyota,IF(E10="Honda",IncentiveRate_Honda,IF(E10="Ford",IncentiveRate_Ford,0))) -> 460.944 | J10: =F10-G10+H10+I10 -> 4534.144 | K10: 1247 | L10: =J10+K10 -> 5781.144 | M10: =K10 -> 1247 | N10: =IF(M10>=TierMinPVR_Platinum,"Platinum",IF(M10>=TierMinPVR_Gold,"Gold",IF(M10>=TierMinPVR_Silver,"Silver","Bronze"))) -> Silver | O10: =J10*VLOOKUP(N10,CommissionTable,3,FALSE) -> 136.02432 | P10: =IF(O10>VLOOKUP(N10,CommissionTable,5,FALSE),J10*VLOOKUP(N10,CommissionTable,4,FALSE),0) -> 0 | Q10: =IF(VLOOKUP(N10,CommissionTable,3,FALSE)>0.03,SUMIFS($J$4:$J$53,$D$4:$D$53,D10,$C$4:$C$53,">"&DATE(2025,1,1))*0.005,0) -> 0 | R10: =O10+P10+Q10 -> 136.02432
A11: N1020 | B11: VINT100020 | C11: 45725 | D11: =TEXT(C11,"mmm") -> Mar | E11: Toyota | F11: 36081 | G11: 33364 | H11: =G11*HoldbackRate -> 834.1 | I11: =G11*IF(E11="Toyota",IncentiveRate_Toyota,IF(E11="Honda",IncentiveRate_Honda,IF(E11="Ford",IncentiveRate_Ford,0))) -> 700.644 | J11: =F11-G11+H11+I11 -> 4251.744 | K11: 1903 | L11: =J11+K11 -> 6154.744 | M11: =K11 -> 1903 | N11: =IF(M11>=TierMinPVR_Platinum,"Platinum",IF(M11>=TierMinPVR_Gold,"Gold",IF(M11>=TierMinPVR_Silver,"Silver","Bronze"))) -> Gold | O11: =J11*VLOOKUP(N11,CommissionTable,3,FALSE) -> 170.06976 | P11: =IF(O11>VLOOKUP(N11,CommissionTable,5,FALSE),J11*VLOOKUP(N11,CommissionTable,4,FALSE),0) -> 0 | Q11: =IF(VLOOKUP(N11,CommissionTable,3,FALSE)>0.03,SUMIFS($J$4:$J$53,$D$4:$D$53,D11,$C$4:$C$53,">"&DATE(2025,1,1))*0.005,0) -> 79.39206 | R11: =O11+P11+Q11 -> 249.46182
A12: N1028 | B12: VINT100028 | C12: 45731 | D12: =TEXT(C12,"mmm") -> Mar | E12: Toyota | F12: 51661 | G12: 48176 | H12: =G12*HoldbackRate -> 1204.4 | I12: =G12*IF(E12="Toyota",IncentiveRate_Toyota,IF(E12="Honda",IncentiveRate_Honda,IF(E12="Ford",IncentiveRate_Ford,0))) -> 1011.696 | J12: =F12-G12+H12+I12 -> 5701.096 | K12: 1339 | L12: =J12+K12 -> 7040.096 | M12: =K12 -> 1339 | N12: =IF(M12>=TierMinPVR_Platinum,"Platinum",IF(M12>=TierMinPVR_Gold,"Gold",IF(M12>=TierMinPVR_Silver,"Silver","Bronze"))) -> Silver | O12: =J12*VLOOKUP(N12,CommissionTable,3,FALSE) -> 171.03288 | P12: =IF(O12>VLOOKUP(N12,CommissionTable,5,FALSE),J12*VLOOKUP(N12,CommissionTable,4,FALSE),0) -> 57.01096 | Q12: =IF(VLOOKUP(N12,CommissionTable,3,FALSE)>0.03,SUMIFS($J$4:$J$53,$D$4:$D$53,D12,$C$4:$C$53,">"&DATE(2025,1,1))*0.005,0) -> 0 | R12: =O12+P12+Q12 -> 228.04384
A13: N1001 | B13: VINT100001 | C13: 45740 | D13: =TEXT(C13,"mmm") -> Mar | E13: Toyota | F13: 50174 | G13: 46382 | H13: =G13*HoldbackRate -> 1159.55 | I13: =G13*IF(E13="Toyota",IncentiveRate_Toyota,IF(E13="Honda",IncentiveRate_Honda,IF(E13="Ford",IncentiveRate_Ford,0))) -> 974.022 | J13: =F13-G13+H13+I13 -> 5925.572 | K13: 1916 | L13: =J13+K13 -> 7841.572 | M13: =K13 -> 1916 | N13: =IF(M13>=TierMinPVR_Platinum,"Platinum",IF(M13>=TierMinPVR_Gold,"Gold",IF(M13>=TierMinPVR_Silver,"Silver","Bronze"))) -> Gold | O13: =J13*VLOOKUP(N13,CommissionTable,3,FALSE) -> 237.02288 | P13: =IF(O13>VLOOKUP(N13,CommissionTable,5,FALSE),J13*VLOOKUP(N13,CommissionTable,4,FALSE),0) -> 0 | Q13: =IF(VLOOKUP(N13,CommissionTable,3,FALSE)>0.03,SUMIFS($J$4:$J$53,$D$4:$D$53,D13,$C$4:$C$53,">"&DATE(2025,1,1))*0.005,0) -> 79.39206 | R13: =O13+P13+Q13 -> 316.41494
A14: N1045 | B14: VINT100045 | C14: 45751 | D14: =TEXT(C14,"mmm") -> Apr | E14: Toyota | F14: 49593 | G14: 44924 | H14: =G14*HoldbackRate -> 1123.1 | I14: =G14*IF(E14="Toyota",IncentiveRate_Toyota,IF(E14="Honda",IncentiveRate_Honda,IF(E14="Ford",IncentiveRate_Ford,0))) -> 943.404 | J14: =F14-G14+H14+I14 -> 6735.504 | K14: 1667 | L14: =J14+K14 -> 8402.504 | M14: =K14 -> 1667 | N14: =IF(M14>=TierMinPVR_Platinum,"Platinum",IF(M14>=TierMinPVR_Gold,"Gold",IF(M14>=TierMinPVR_Silver,"Silver","Bronze"))) -> Silver | O14: =J14*VLOOKUP(N14,CommissionTable,3,FALSE) -> 202.06512 | P14: =IF(O14>VLOOKUP(N14,CommissionTable,5,FALSE),J14*VLOOKUP(N14,CommissionTable,4,FALSE),0) -> 67.35504 | Q14: =IF(VLOOKUP(N14,CommissionTable,3,FALSE)>0.03,SUMIFS($J$4:$J$53,$D$4:$D$53,D14,$C$4:$C$53,">"&DATE(2025,1,1))*0.005,0) -> 0 | R14: =O14+P14+Q14 -> 269.42016
A15: N1003 | B15: VINF100003 | C15: 45764 | D15: =TEXT(C15,"mmm") -> Apr | E15: Ford | F15: 28869 | G15: 26376 | H15: =G15*HoldbackRate -> 659.4 | I15: =G15*IF(E15="Toyota",IncentiveRate_Toyota,IF(E15="Honda",IncentiveRate_Honda,IF(E15="Ford",IncentiveRate_Ford,0))) -> 659.4 | J15: =F15-G15+H15+I15 -> 3811.8 | K15: 2266 | L15: =J15+K15 -> 6077.8 | M15: =K15 -> 2266 | N15: =IF(M15>=TierMinPVR_Platinum,"Platinum",IF(M15>=TierMinPVR_Gold,"Gold",IF(M15>=TierMinPVR_Silver,"Silver","Bronze"))) -> Gold | O15: =J15*VLOOKUP(N15,CommissionTable,3,FALSE) -> 152.472 | P15: =IF(O15>VLOOKUP(N15,CommissionTable,5,FALSE),J15*VLOOKUP(N15,CommissionTable,4,FALSE),0) -> 0 | Q15: =IF(VLOOKUP(N15,CommissionTable,3,FALSE)>0.03,SUMIFS($J$4:$J$53,$D$4:$D$53,D15,$C$4:$C$53,">"&DATE(2025,1,1))*0.005,0) -> 148.22229 | R15: =O15+P15+Q15 -> 300.69429
... A53: N1014 | B53: VINF100014 | C53: 46013 | D53: =TEXT(C53,"mmm") -> Dec | E53: Ford | F53: 30339 | G53: 27807 | H53: =G53*HoldbackRate -> 695.175 | I53: =G53*IF(E53="Toyota",IncentiveRate_Toyota,IF(E53="Honda",IncentiveRate_Honda,IF(E53="Ford",IncentiveRate_Ford,0))) -> 695.175 | J53: =F53-G53+H53+I53 -> 3922.35 | K53: 1150 | L53: =J53+K53 -> 5072.35 | M53: =K53 -> 1150 | N53: =IF(M53>=TierMinPVR_Platinum,"Platinum",IF(M53>=TierMinPVR_Gold,"Gold",IF(M53>=TierMinPVR_Silver,"Silver","Bronze"))) -> Bronze | O53: =J53*VLOOKUP(N53,CommissionTable,3,FALSE) -> 78.447 | P53: =IF(O53>VLOOKUP(N53,CommissionTable,5,FALSE),J53*VLOOKUP(N53,CommissionTable,4,FALSE),0) -> 0 | Q53: =IF(VLOOKUP(N53,CommissionTable,3,FALSE)>0.03,SUMIFS($J$4:$J$53,$D$4:$D$53,D53,$C$4:$C$53,">"&DATE(2025,1,1))*0.005,0) -> 0 | R53: =O53+P53+Q53 -> 78.447
A56: MONTHLY SUMMARY
A57: Month | B57: Unit Count | C57: Avg Front Gross | D57: Total Front Gross | E57: Total F&I | F57: Avg F&I PVR | G57: Total Gross
A58: Jan | B58: =COUNTIFS($D$4:$D$53,A58) -> 3 | C58: =IFERROR(AVERAGEIFS($J$4:$J$53,$D$4:$D$53,A58),0) -> 6511.096 | D58: =SUMIFS($J$4:$J$53,$D$4:$D$53,A58) -> 19533.288 | E58: =SUMIFS($K$4:$K$53,$D$4:$D$53,A58) -> 4733 | F58: =IFERROR(E58/B58,0) -> 1577.6667 | G58: =D58+E58 -> 24266.288
A59: Feb | B59: =COUNTIFS($D$4:$D$53,A59) -> 4 | C59: =IFERROR(AVERAGEIFS($J$4:$J$53,$D$4:$D$53,A59),0) -> 5783.4965 | D59: =SUMIFS($J$4:$J$53,$D$4:$D$53,A59) -> 23133.986 | E59: =SUMIFS($K$4:$K$53,$D$4:$D$53,A59) -> 6133 | F59: =IFERROR(E59/B59,0) -> 1533.25 | G59: =D59+E59 -> 29266.986
A60: Mar | B60: =COUNTIFS($D$4:$D$53,A60) -> 3 | C60: =IFERROR(AVERAGEIFS($J$4:$J$53,$D$4:$D$53,A60),0) -> 5292.804 | D60: =SUMIFS($J$4:$J$53,$D$4:$D$53,A60) -> 15878.412 | E60: =SUMIFS($K$4:$K$53,$D$4:$D$53,A60) -> 5158 | F60: =IFERROR(E60/B60,0) -> 1719.3333 | G60: =D60+E60 -> 21036.412
A61: Apr | B61: =COUNTIFS($D$4:$D$53,A61) -> 5 | C61: =IFERROR(AVERAGEIFS($J$4:$J$53,$D$4:$D$53,A61),0) -> 5928.8916 | D61: =SUMIFS($J$4:$J$53,$D$4:$D$53,A61) -> 29644.458 | E61: =SUMIFS($K$4:$K$53,$D$4:$D$53,A61) -> 9441 | F61: =IFERROR(E61/B61,0) -> 1888.2 | G61: =D61+E61 -> 39085.458
A62: May | B62: =COUNTIFS($D$4:$D$53,A62) -> 3 | C62: =IFERROR(AVERAGEIFS($J$4:$J$53,$D$4:$D$53,A62),0) -> 5653.2987 | D62: =SUMIFS($J$4:$J$53,$D$4:$D$53,A62) -> 16959.896 | E62: =SUMIFS($K$4:$K$53,$D$4:$D$53,A62) -> 5536 | F62: =IFERROR(E62/B62,0) -> 1845.3333 | G62: =D62+E62 -> 22495.896
A63: Jun | B63: =COUNTIFS($D$4:$D$53,A63) -> 7 | C63: =IFERROR(AVERAGEIFS($J$4:$J$53,$D$4:$D$53,A63),0) -> 6013.8426 | D63: =SUMIFS($J$4:$J$53,$D$4:$D$53,A63) -> 42096.898 | E63: =SUMIFS($K$4:$K$53,$D$4:$D$53,A63) -> 15049 | F63: =IFERROR(E63/B63,0) -> 2149.8571 | G63: =D63+E63 -> 57145.898
A64: Jul | B64: =COUNTIFS($D$4:$D$53,A64) -> 4 | C64: =IFERROR(AVERAGEIFS($J$4:$J$53,$D$4:$D$53,A64),0) -> 5086.0045 | D64: =SUMIFS($J$4:$J$53,$D$4:$D$53,A64) -> 20344.018 | E64: =SUMIFS($K$4:$K$53,$D$4:$D$53,A64) -> 9035 | F64: =IFERROR(E64/B64,0) -> 2258.75 | G64: =D64+E64 -> 29379.018
A65: Aug | B65: =COUNTIFS($D$4:$D$53,A65) -> 2 | C65: =IFERROR(AVERAGEIFS($J$4:$J$53,$D$4:$D$53,A65),0) -> 5273.3045 | D65: =SUMIFS($J$4:$J$53,$D$4:$D$53,A65) -> 10546.609 | E65: =SUMIFS($K$4:$K$53,$D$4:$D$53,A65) -> 1666 | F65: =IFERROR(E65/B65,0) -> 833 | G65: =D65+E65 -> 12212.609
A66: Sep | B66: =COUNTIFS($D$4:$D$53,A66) -> 6 | C66: =IFERROR(AVERAGEIFS($J$4:$J$53,$D$4:$D$53,A66),0) -> 4542.1067 | D66: =SUMIFS($J$4:$J$53,$D$4:$D$53,A66) -> 27252.64 | E66: =SUMIFS($K$4:$K$53,$D$4:$D$53,A66) -> 11866 | F66: =IFERROR(E66/B66,0) -> 1977.6667 | G66: =D66+E66 -> 39118.64
A67: Oct | B67: =COUNTIFS($D$4:$D$53,A67) -> 3 | C67: =IFERROR(AVERAGEIFS($J$4:$J$53,$D$4:$D$53,A67),0) -> 7018.3087 | D67: =SUMIFS($J$4:$J$53,$D$4:$D$53,A67) -> 21054.926 | E67: =SUMIFS($K$4:$K$53,$D$4:$D$53,A67) -> 3519 | F67: =IFERROR(E67/B67,0) -> 1173 | G67: =D67+E67 -> 24573.926
A68: Nov | B68: =COUNTIFS($D$4:$D$53,A68) -> 8 | C68: =IFERROR(AVERAGEIFS($J$4:$J$53,$D$4:$D$53,A68),0) -> 5844.611 | D68: =SUMIFS($J$4:$J$53,$D$4:$D$53,A68) -> 46756.888 | E68: =SUMIFS($K$4:$K$53,$D$4:$D$53,A68) -> 13940 | F68: =IFERROR(E68/B68,0) -> 1742.5 | G68: =D68+E68 -> 60696.888
A69: Dec | B69: =COUNTIFS($D$4:$D$53,A69) -> 2 | C69: =IFERROR(AVERAGEIFS($J$4:$J$53,$D$4:$D$53,A69),0) -> 4741.507 | D69: =SUMIFS($J$4:$J$53,$D$4:$D$53,A69) -> 9483.014 | E69: =SUMIFS($K$4:$K$53,$D$4:$D$53,A69) -> 2014 | F69: =IFERROR(E69/B69,0) -> 1007 | G69: =D69+E69 -> 11497.014
A70: TOTAL | B70: =SUM(B58:B69) -> 50 | C70: =IFERROR(D70/B70,0) -> 5653.7007 | D70: =SUM(D58:D69) -> 282685.03 | E70: =SUM(E58:E69) -> 88090 | F70: =IFERROR(E70/B70,0) -> 1761.8 | G70: =SUM(G58:G69) -> 370775.03

Sheet Used Vehicle
A1: USED VEHICLE DEAL LOG
A3: Stock# | B3: VIN | C3: Sale Date | D3: Month | E3: Acq Source | F3: Days on Lot | G3: Sale Price | H3: Acquisition Cost | I3: Recon Cost | J3: Floor Plan Interest | K3: F&I Revenue | L3: Adjusted Gross | M3: Total Gross | N3: Gross %
A4: U2005 | B4: VINU200005 | C4: 45659 | D4: =TEXT(C4,"mmm") -> Jan | E4: Direct | F4: 71 | G4: 30477 | H4: 25536 | I4: 1337 | J4: =F4*H4*RiskAdjustedFloorPlanRate/365 -> 362.73538 | K4: 922 | L4: =G4-H4-I4-J4 -> 3241.2646 | M4: =L4+K4 -> 4163.2646 | N4: =IFERROR(M4/G4,0) -> 0.13660349
A5: U2028 | B5: VINU200028 | C5: 45661 | D5: =TEXT(C5,"mmm") -> Jan | E5: Auction | F5: 32 | G5: 33024 | H5: 27884 | I5: 793 | J5: =F5*H5*RiskAdjustedFloorPlanRate/365 -> 178.51872 | K5: 678 | L5: =G5-H5-I5-J5 -> 4168.4813 | M5: =L5+K5 -> 4846.4813 | N5: =IFERROR(M5/G5,0) -> 0.14675634
A6: U2002 | B6: VINU200002 | C6: 45663 | D6: =TEXT(C6,"mmm") -> Jan | E6: Auction | F6: 10 | G6: 26793 | H6: 19820 | I6: 1181 | J6: =F6*H6*RiskAdjustedFloorPlanRate/365 -> 39.653575 | K6: 1184 | L6: =G6-H6-I6-J6 -> 5752.3464 | M6: =L6+K6 -> 6936.3464 | N6: =IFERROR(M6/G6,0) -> 0.25888652
A7: U2023 | B7: VINU200023 | C7: 45663 | D7: =TEXT(C7,"mmm") -> Jan | E7: Direct | F7: 52 | G7: 39637 | H7: 33280 | I7: 1621 | J7: =F7*H7*RiskAdjustedFloorPlanRate/365 -> 346.23053 | K7: 2105 | L7: =G7-H7-I7-J7 -> 4389.7695 | M7: =L7+K7 -> 6494.7695 | N7: =IFERROR(M7/G7,0) -> 0.16385623
A8: U2006 | B8: VINU200006 | C8: 45674 | D8: =TEXT(C8,"mmm") -> Jan | E8: Trade-in | F8: 33 | G8: 16245 | H8: 12821 | I8: 1632 | J8: =F8*H8*RiskAdjustedFloorPlanRate/365 -> 84.647579 | K8: 1081 | L8: =G8-H8-I8-J8 -> 1707.3524 | M8: =L8+K8 -> 2788.3524 | N8: =IFERROR(M8/G8,0) -> 0.17164373
A9: U2031 | B9: VINU200031 | C9: 45674 | D9: =TEXT(C9,"mmm") -> Jan | E9: Direct | F9: 95 | G9: 20456 | H9: 15436 | I9: 393 | J9: =F9*H9*RiskAdjustedFloorPlanRate/365 -> 293.38444 | K9: 1960 | L9: =G9-H9-I9-J9 -> 4333.6156 | M9: =L9+K9 -> 6293.6156 | N9: =IFERROR(M9/G9,0) -> 0.30766599
A10: U2026 | B10: VINU200026 | C10: 45679 | D10: =TEXT(C10,"mmm") -> Jan | E10: Trade-in | F10: 61 | G10: 24756 | H10: 18363 | I10: 392 | J10: =F10*H10*RiskAdjustedFloorPlanRate/365 -> 224.10532 | K10: 2183 | L10: =G10-H10-I10-J10 -> 5776.8947 | M10: =L10+K10 -> 7959.8947 | N10: =IFERROR(M10/G10,0) -> 0.32153396
A11: U2019 | B11: VINU200019 | C11: 45691 | D11: =TEXT(C11,"mmm") -> Feb | E11: Direct | F11: 29 | G11: 31877 | H11: 22486 | I11: 1006 | J11: =F11*H11*RiskAdjustedFloorPlanRate/365 -> 130.46346 | K11: 1792 | L11: =G11-H11-I11-J11 -> 8254.5365 | M11: =L11+K11 -> 10046.537 | N11: =IFERROR(M11/G11,0) -> 0.31516568
A12: U2000 | B12: VINU200000 | C12: 45703 | D12: =TEXT(C12,"mmm") -> Feb | E12: Direct | F12: 22 | G12: 15657 | H12: 12491 | I12: 1357 | J12: =F12*H12*RiskAdjustedFloorPlanRate/365 -> 54.979222 | K12: 630 | L12: =G12-H12-I12-J12 -> 1754.0208 | M12: =L12+K12 -> 2384.0208 | N12: =IFERROR(M12/G12,0) -> 0.15226549
A13: U2011 | B13: VINU200011 | C13: 45706 | D13: =TEXT(C13,"mmm") -> Feb | E13: Trade-in | F13: 74 | G13: 22690 | H13: 16333 | I13: 964 | J13: =F13*H13*RiskAdjustedFloorPlanRate/365 -> 241.81118 | K13: 740 | L13: =G13-H13-I13-J13 -> 5151.1888 | M13: =L13+K13 -> 5891.1888 | N13: =IFERROR(M13/G13,0) -> 0.25963811
A14: U2029 | B14: VINU200029 | C14: 45708 | D14: =TEXT(C14,"mmm") -> Feb | E14: Auction | F14: 54 | G14: 37872 | H14: 30977 | I14: 1143 | J14: =F14*H14*RiskAdjustedFloorPlanRate/365 -> 334.66617 | K14: 1841 | L14: =G14-H14-I14-J14 -> 5417.3338 | M14: =L14+K14 -> 7258.3338 | N14: =IFERROR(M14/G14,0) -> 0.19165436
A15: U2001 | B15: VINU200001 | C15: 45713 | D15: =TEXT(C15,"mmm") -> Feb | E15: Trade-in | F15: 31 | G15: 27317 | H15: 21111 | I15: 687 | J15: =F15*H15*RiskAdjustedFloorPlanRate/365 -> 130.93302 | K15: 1421 | L15: =G15-H15-I15-J15 -> 5388.067 | M15: =L15+K15 -> 6809.067 | N15: =IFERROR(M15/G15,0) -> 0.24926116
... A53: U2045 | B53: VINU200045 | C53: 46008 | D53: =TEXT(C53,"mmm") -> Dec | E53: Auction | F53: 80 | G53: 28611 | H53: 23878 | I53: 1773 | J53: =F53*H53*RiskAdjustedFloorPlanRate/365 -> 382.17884 | K53: 1572 | L53: =G53-H53-I53-J53 -> 2577.8212 | M53: =L53+K53 -> 4149.8212 | N53: =IFERROR(M53/G53,0) -> 0.14504286
A56: MONTHLY SUMMARY (SUMPRODUCT weighted)
A57: Month | B57: Units | C57: Total Sale $ | D57: Weighted Avg Gross | E57: Total Adj Gross | F57: Avg Days on Lot | G57: Total F&I | H57: Total Gross
A58: Jan | B58: =COUNTIFS($D$4:$D$53,A58) -> 7 | C58: =SUMIFS($G$4:$G$53,$D$4:$D$53,A58) -> 191388 | D58: =IFERROR(SUMPRODUCT(($D$4:$D$53=A58)*$L$4:$L$53)/MAX(COUNTIFS($D$4:$D$53,A58),1),0) -> 4195.6749 | E58: =SUMIFS($L$4:$L$53,$D$4:$D$53,A58) -> 29369.724 | F58: =IFERROR(SUMPRODUCT(($D$4:$D$53=A58)*$F$4:$F$53)/MAX(COUNTIFS($D$4:$D$53,A58),1),0) -> 50.571429 | G58: =SUMIFS($K$4:$K$53,$D$4:$D$53,A58) -> 10113 | H58: =SUMIFS($M$4:$M$53,$D$4:$D$53,A58) -> 39482.724
A59: Feb | B59: =COUNTIFS($D$4:$D$53,A59) -> 5 | C59: =SUMIFS($G$4:$G$53,$D$4:$D$53,A59) -> 135413 | D59: =IFERROR(SUMPRODUCT(($D$4:$D$53=A59)*$L$4:$L$53)/MAX(COUNTIFS($D$4:$D$53,A59),1),0) -> 5193.0294 | E59: =SUMIFS($L$4:$L$53,$D$4:$D$53,A59) -> 25965.147 | F59: =IFERROR(SUMPRODUCT(($D$4:$D$53=A59)*$F$4:$F$53)/MAX(COUNTIFS($D$4:$D$53,A59),1),0) -> 42 | G59: =SUMIFS($K$4:$K$53,$D$4:$D$53,A59) -> 6424 | H59: =SUMIFS($M$4:$M$53,$D$4:$D$53,A59) -> 32389.147
A60: Mar | B60: =COUNTIFS($D$4:$D$53,A60) -> 2 | C60: =SUMIFS($G$4:$G$53,$D$4:$D$53,A60) -> 48495 | D60: =IFERROR(SUMPRODUCT(($D$4:$D$53=A60)*$L$4:$L$53)/MAX(COUNTIFS($D$4:$D$53,A60),1),0) -> 4108.2772 | E60: =SUMIFS($L$4:$L$53,$D$4:$D$53,A60) -> 8216.5543 | F60: =IFERROR(SUMPRODUCT(($D$4:$D$53=A60)*$F$4:$F$53)/MAX(COUNTIFS($D$4:$D$53,A60),1),0) -> 52.5 | G60: =SUMIFS($K$4:$K$53,$D$4:$D$53,A60) -> 3561 | H60: =SUMIFS($M$4:$M$53,$D$4:$D$53,A60) -> 11777.554
A61: Apr | B61: =COUNTIFS($D$4:$D$53,A61) -> 8 | C61: =SUMIFS($G$4:$G$53,$D$4:$D$53,A61) -> 232006 | D61: =IFERROR(SUMPRODUCT(($D$4:$D$53=A61)*$L$4:$L$53)/MAX(COUNTIFS($D$4:$D$53,A61),1),0) -> 5024.8747 | E61: =SUMIFS($L$4:$L$53,$D$4:$D$53,A61) -> 40198.998 | F61: =IFERROR(SUMPRODUCT(($D$4:$D$53=A61)*$F$4:$F$53)/MAX(COUNTIFS($D$4:$D$53,A61),1),0) -> 47 | G61: =SUMIFS($K$4:$K$53,$D$4:$D$53,A61) -> 11037 | H61: =SUMIFS($M$4:$M$53,$D$4:$D$53,A61) -> 51235.998
A62: May | B62: =COUNTIFS($D$4:$D$53,A62) -> 5 | C62: =SUMIFS($G$4:$G$53,$D$4:$D$53,A62) -> 138771 | D62: =IFERROR(SUMPRODUCT(($D$4:$D$53=A62)*$L$4:$L$53)/MAX(COUNTIFS($D$4:$D$53,A62),1),0) -> 3960.6571 | E62: =SUMIFS($L$4:$L$53,$D$4:$D$53,A62) -> 19803.285 | F62: =IFERROR(SUMPRODUCT(($D$4:$D$53=A62)*$F$4:$F$53)/MAX(COUNTIFS($D$4:$D$53,A62),1),0) -> 59 | G62: =SUMIFS($K$4:$K$53,$D$4:$D$53,A62) -> 4803 | H62: =SUMIFS($M$4:$M$53,$D$4:$D$53,A62) -> 24606.285
A63: Jun | B63: =COUNTIFS($D$4:$D$53,A63) -> 2 | C63: =SUMIFS($G$4:$G$53,$D$4:$D$53,A63) -> 60321 | D63: =IFERROR(SUMPRODUCT(($D$4:$D$53=A63)*$L$4:$L$53)/MAX(COUNTIFS($D$4:$D$53,A63),1),0) -> 7189.3073 | E63: =SUMIFS($L$4:$L$53,$D$4:$D$53,A63) -> 14378.615 | F63: =IFERROR(SUMPRODUCT(($D$4:$D$53=A63)*$F$4:$F$53)/MAX(COUNTIFS($D$4:$D$53,A63),1),0) -> 57 | G63: =SUMIFS($K$4:$K$53,$D$4:$D$53,A63) -> 3659 | H63: =SUMIFS($M$4:$M$53,$D$4:$D$53,A63) -> 18037.615
A64: Jul | B64: =COUNTIFS($D$4:$D$53,A64) -> 4 | C64: =SUMIFS($G$4:$G$53,$D$4:$D$53,A64) -> 135241 | D64: =IFERROR(SUMPRODUCT(($D$4:$D$53=A64)*$L$4:$L$53)/MAX(COUNTIFS($D$4:$D$53,A64),1),0) -> 6262.477 | E64: =SUMIFS($L$4:$L$53,$D$4:$D$53,A64) -> 25049.908 | F64: =IFERROR(SUMPRODUCT(($D$4:$D$53=A64)*$F$4:$F$53)/MAX(COUNTIFS($D$4:$D$53,A64),1),0) -> 72.75 | G64: =SUMIFS($K$4:$K$53,$D$4:$D$53,A64) -> 4278 | H64: =SUMIFS($M$4:$M$53,$D$4:$D$53,A64) -> 29327.908
A65: Aug | B65: =COUNTIFS($D$4:$D$53,A65) -> 2 | C65: =SUMIFS($G$4:$G$53,$D$4:$D$53,A65) -> 64884 | D65: =IFERROR(SUMPRODUCT(($D$4:$D$53=A65)*$L$4:$L$53)/MAX(COUNTIFS($D$4:$D$53,A65),1),0) -> 6812.1321 | E65: =SUMIFS($L$4:$L$53,$D$4:$D$53,A65) -> 13624.264 | F65: =IFERROR(SUMPRODUCT(($D$4:$D$53=A65)*$F$4:$F$53)/MAX(COUNTIFS($D$4:$D$53,A65),1),0) -> 66 | G65: =SUMIFS($K$4:$K$53,$D$4:$D$53,A65) -> 3143 | H65: =SUMIFS($M$4:$M$53,$D$4:$D$53,A65) -> 16767.264
A66: Sep | B66: =COUNTIFS($D$4:$D$53,A66) -> 2 | C66: =SUMIFS($G$4:$G$53,$D$4:$D$53,A66) -> 35598 | D66: =IFERROR(SUMPRODUCT(($D$4:$D$53=A66)*$L$4:$L$53)/MAX(COUNTIFS($D$4:$D$53,A66),1),0) -> 3428.6923 | E66: =SUMIFS($L$4:$L$53,$D$4:$D$53,A66) -> 6857.3847 | F66: =IFERROR(SUMPRODUCT(($D$4:$D$53=A66)*$F$4:$F$53)/MAX(COUNTIFS($D$4:$D$53,A66),1),0) -> 54.5 | G66: =SUMIFS($K$4:$K$53,$D$4:$D$53,A66) -> 2825 | H66: =SUMIFS($M$4:$M$53,$D$4:$D$53,A66) -> 9682.3847
A67: Oct | B67: =COUNTIFS($D$4:$D$53,A67) -> 3 | C67: =SUMIFS($G$4:$G$53,$D$4:$D$53,A67) -> 74899 | D67: =IFERROR(SUMPRODUCT(($D$4:$D$53=A67)*$L$4:$L$53)/MAX(COUNTIFS($D$4:$D$53,A67),1),0) -> 4869.1402 | E67: =SUMIFS($L$4:$L$53,$D$4:$D$53,A67) -> 14607.421 | F67: =IFERROR(SUMPRODUCT(($D$4:$D$53=A67)*$F$4:$F$53)/MAX(COUNTIFS($D$4:$D$53,A67),1),0) -> 65.666667 | G67: =SUMIFS($K$4:$K$53,$D$4:$D$53,A67) -> 3687 | H67: =SUMIFS($M$4:$M$53,$D$4:$D$53,A67) -> 18294.421
A68: Nov | B68: =COUNTIFS($D$4:$D$53,A68) -> 8 | C68: =SUMIFS($G$4:$G$53,$D$4:$D$53,A68) -> 201306 | D68: =IFERROR(SUMPRODUCT(($D$4:$D$53=A68)*$L$4:$L$53)/MAX(COUNTIFS($D$4:$D$53,A68),1),0) -> 3736.9711 | E68: =SUMIFS($L$4:$L$53,$D$4:$D$53,A68) -> 29895.768 | F68: =IFERROR(SUMPRODUCT(($D$4:$D$53=A68)*$F$4:$F$53)/MAX(COUNTIFS($D$4:$D$53,A68),1),0) -> 58.625 | G68: =SUMIFS($K$4:$K$53,$D$4:$D$53,A68) -> 11095 | H68: =SUMIFS($M$4:$M$53,$D$4:$D$53,A68) -> 40990.768
A69: Dec | B69: =COUNTIFS($D$4:$D$53,A69) -> 2 | C69: =SUMIFS($G$4:$G$53,$D$4:$D$53,A69) -> 49781 | D69: =IFERROR(SUMPRODUCT(($D$4:$D$53=A69)*$L$4:$L$53)/MAX(COUNTIFS($D$4:$D$53,A69),1),0) -> 3249.4641 | E69: =SUMIFS($L$4:$L$53,$D$4:$D$53,A69) -> 6498.9282 | F69: =IFERROR(SUMPRODUCT(($D$4:$D$53=A69)*$F$4:$F$53)/MAX(COUNTIFS($D$4:$D$53,A69),1),0) -> 72 | G69: =SUMIFS($K$4:$K$53,$D$4:$D$53,A69) -> 3232 | H69: =SUMIFS($M$4:$M$53,$D$4:$D$53,A69) -> 9730.9282
A70: TOTAL | B70: =SUM(B58:B69) -> 50 | C70: =SUM(C58:C69) -> 1368103 | E70: =SUM(E58:E69) -> 234466 | G70: =SUM(G58:G69) -> 67857 | H70: =SUM(H58:H69) -> 302323

Sheet F&I Detail
A1: F&I PRODUCT DETAIL
A3: FI_ID | B3: Deal# | C3: Deal Type | D3: Month | E3: Product Type | F3: Product Cost | G3: Product Revenue | H3: Reserve | I3: Penetration Flag | J3: Net Income
A4: FI3067 | B4: U2028 | C4: Used | D4: Jan | E4: Tire&Wheel | F4: 627 | G4: 1524 | H4: 224 | I4: 1 | J4: =G4-F4+H4 -> 1121
A5: FI3000 | B5: U2023 | C5: Used | D5: Jan | E5: VSC | F5: 461 | G5: 923 | H5: 199 | I5: 1 | J5: =G5-F5+H5 -> 661
A6: FI3026 | B6: U2023 | C6: Used | D6: Jan | E6: Maintenance | F6: 272 | G6: 716 | H6: 185 | I6: 1 | J6: =G6-F6+H6 -> 629
A7: FI3060 | B7: U2002 | C7: Used | D7: Jan | E7: Maintenance | F7: 818 | G7: 1911 | H7: 149 | I7: 1 | J7: =G7-F7+H7 -> 1242
A8: FI3080 | B8: U2002 | C8: Used | D8: Jan | E8: VSC | F8: 358 | G8: 884 | H8: 318 | I8: 1 | J8: =G8-F8+H8 -> 844
A9: FI3101 | B9: U2002 | C9: Used | D9: Jan | E9: KeyReplacement | F9: 736 | G9: 2486 | H9: 240 | I9: 1 | J9: =G9-F9+H9 -> 1990
A10: FI3063 | B10: U2006 | C10: Used | D10: Jan | E10: VSC | F10: 512 | G10: 1615 | H10: 76 | I10: 1 | J10: =G10-F10+H10 -> 1179
A11: FI3050 | B11: U2026 | C11: Used | D11: Jan | E11: Tire&Wheel | F11: 473 | G11: 877 | H11: 129 | I11: 1 | J11: =G11-F11+H11 -> 533
A12: FI3066 | B12: U2026 | C12: Used | D12: Jan | E12: VSC | F12: 666 | G12: 1459 | H12: 358 | I12: 1 | J12: =G12-F12+H12 -> 1151
A13: FI3083 | B13: U2026 | C13: Used | D13: Jan | E13: KeyReplacement | F13: 427 | G13: 1492 | H13: 322 | I13: 1 | J13: =G13-F13+H13 -> 1387
A14: FI3085 | B14: N1011 | C14: New | D14: Jan | E14: Appearance | F14: 371 | G14: 1335 | H14: 116 | I14: 1 | J14: =G14-F14+H14 -> 1080
A15: FI3013 | B15: N1023 | C15: New | D15: Jan | E15: KeyReplacement | F15: 426 | G15: 1604 | H15: 358 | I15: 1 | J15: =G15-F15+H15 -> 1536
... A153: FI3118 | B153: N1014 | C153: New | D153: Dec | E153: Maintenance | F153: 230 | G153: 718 | H153: 585 | I153: 1 | J153: =G153-F153+H153 -> 1073
A156: STORE-LEVEL PVR (cross-sheet)
A157: Month | B157: F&I Net Income | C157: Total Units (NV+UV) | D157: Store PVR | E157: Target | F157: Variance | G157: % of Target
A158: Jan | B158: =SUMIFS($J$4:$J$153,$D$4:$D$153,A158) -> 15810 | C158: =COUNTIFS(NV_Month,A158)+COUNTIFS(UV_Month,A158) -> 10 | D158: =IFERROR(B158/C158,0) -> 1581 | E158: =FI_PVR_Target -> 1600 | F158: =D158-E158 -> -19 | G158: =IFERROR(D158/E158,0) -> 0.988125
A159: Feb | B159: =SUMIFS($J$4:$J$153,$D$4:$D$153,A159) -> 10467 | C159: =COUNTIFS(NV_Month,A159)+COUNTIFS(UV_Month,A159) -> 9 | D159: =IFERROR(B159/C159,0) -> 1163 | E159: =FI_PVR_Target -> 1600 | F159: =D159-E159 -> -437 | G159: =IFERROR(D159/E159,0) -> 0.726875
A160: Mar | B160: =SUMIFS($J$4:$J$153,$D$4:$D$153,A160) -> 5503 | C160: =COUNTIFS(NV_Month,A160)+COUNTIFS(UV_Month,A160) -> 5 | D160: =IFERROR(B160/C160,0) -> 1100.6 | E160: =FI_PVR_Target -> 1600 | F160: =D160-E160 -> -499.4 | G160: =IFERROR(D160/E160,0) -> 0.687875
A161: Apr | B161: =SUMIFS($J$4:$J$153,$D$4:$D$153,A161) -> 23206 | C161: =COUNTIFS(NV_Month,A161)+COUNTIFS(UV_Month,A161) -> 13 | D161: =IFERROR(B161/C161,0) -> 1785.0769 | E161: =FI_PVR_Target -> 1600 | F161: =D161-E161 -> 185.07692 | G161: =IFERROR(D161/E161,0) -> 1.1156731
A162: May | B162: =SUMIFS($J$4:$J$153,$D$4:$D$153,A162) -> 15493 | C162: =COUNTIFS(NV_Month,A162)+COUNTIFS(UV_Month,A162) -> 8 | D162: =IFERROR(B162/C162,0) -> 1936.625 | E162: =FI_PVR_Target -> 1600 | F162: =D162-E162 -> 336.625 | G162: =IFERROR(D162/E162,0) -> 1.2103906
A163: Jun | B163: =SUMIFS($J$4:$J$153,$D$4:$D$153,A163) -> 17787 | C163: =COUNTIFS(NV_Month,A163)+COUNTIFS(UV_Month,A163) -> 9 | D163: =IFERROR(B163/C163,0) -> 1976.3333 | E163: =FI_PVR_Target -> 1600 | F163: =D163-E163 -> 376.33333 | G163: =IFERROR(D163/E163,0) -> 1.2352083
A164: Jul | B164: =SUMIFS($J$4:$J$153,$D$4:$D$153,A164) -> 12583 | C164: =COUNTIFS(NV_Month,A164)+COUNTIFS(UV_Month,A164) -> 8 | D164: =IFERROR(B164/C164,0) -> 1572.875 | E164: =FI_PVR_Target -> 1600 | F164: =D164-E164 -> -27.125 | G164: =IFERROR(D164/E164,0) -> 0.98304687
A165: Aug | B165: =SUMIFS($J$4:$J$153,$D$4:$D$153,A165) -> 5448 | C165: =COUNTIFS(NV_Month,A165)+COUNTIFS(UV_Month,A165) -> 4 | D165: =IFERROR(B165/C165,0) -> 1362 | E165: =FI_PVR_Target -> 1600 | F165: =D165-E165 -> -238 | G165: =IFERROR(D165/E165,0) -> 0.85125
A166: Sep | B166: =SUMIFS($J$4:$J$153,$D$4:$D$153,A166) -> 14403 | C166: =COUNTIFS(NV_Month,A166)+COUNTIFS(UV_Month,A166) -> 8 | D166: =IFERROR(B166/C166,0) -> 1800.375 | E166: =FI_PVR_Target -> 1600 | F166: =D166-E166 -> 200.375 | G166: =IFERROR(D166/E166,0) -> 1.1252344
A167: Oct | B167: =SUMIFS($J$4:$J$153,$D$4:$D$153,A167) -> 15411 | C167: =COUNTIFS(NV_Month,A167)+COUNTIFS(UV_Month,A167) -> 6 | D167: =IFERROR(B167/C167,0) -> 2568.5 | E167: =FI_PVR_Target -> 1600 | F167: =D167-E167 -> 968.5 | G167: =IFERROR(D167/E167,0) -> 1.6053125
A168: Nov | B168: =SUMIFS($J$4:$J$153,$D$4:$D$153,A168) -> 35653 | C168: =COUNTIFS(NV_Month,A168)+COUNTIFS(UV_Month,A168) -> 16 | D168: =IFERROR(B168/C168,0) -> 2228.3125 | E168: =FI_PVR_Target -> 1600 | F168: =D168-E168 -> 628.3125 | G168: =IFERROR(D168/E168,0) -> 1.3926953
A169: Dec | B169: =SUMIFS($J$4:$J$153,$D$4:$D$153,A169) -> 7160 | C169: =COUNTIFS(NV_Month,A169)+COUNTIFS(UV_Month,A169) -> 4 | D169: =IFERROR(B169/C169,0) -> 1790 | E169: =FI_PVR_Target -> 1600 | F169: =D169-E169 -> 190 | G169: =IFERROR(D169/E169,0) -> 1.11875

Sheet Service & Parts
A1: SERVICE & PARTS REPAIR ORDERS
A3: RO# | B3: Date | C3: Month | D3: Type | E3: Labor Revenue | F3: Labor Cost | G3: Parts Revenue | H3: Parts Cost | I3: Total Revenue | J3: Total Gross
A4: RO5124 | B4: 45662 | C4: =TEXT(B4,"mmm") -> Jan | D4: Warranty | E4: 471 | F4: 198 | G4: 273 | H4: 169 | I4: =E4+G4 -> 744 | J4: =(E4-F4)+(G4-H4) -> 377
A5: RO5173 | B5: 45665 | C5: =TEXT(B5,"mmm") -> Jan | D5: Customer Pay | E5: 183 | F5: 71 | G5: 507 | H5: 324 | I5: =E5+G5 -> 690 | J5: =(E5-F5)+(G5-H5) -> 295
A6: RO5055 | B6: 45669 | C6: =TEXT(B6,"mmm") -> Jan | D6: Customer Pay | E6: 299 | F6: 105 | G6: 547 | H6: 316 | I6: =E6+G6 -> 846 | J6: =(E6-F6)+(G6-H6) -> 425
A7: RO5059 | B7: 45671 | C7: =TEXT(B7,"mmm") -> Jan | D7: Customer Pay | E7: 816 | F7: 273 | G7: 504 | H7: 323 | I7: =E7+G7 -> 1320 | J7: =(E7-F7)+(G7-H7) -> 724
A8: RO5163 | B8: 45672 | C8: =TEXT(B8,"mmm") -> Jan | D8: Customer Pay | E8: 505 | F8: 186 | G8: 109 | H8: 69 | I8: =E8+G8 -> 614 | J8: =(E8-F8)+(G8-H8) -> 359
A9: RO5198 | B9: 45675 | C9: =TEXT(B9,"mmm") -> Jan | D9: Warranty | E9: 66 | F9: 23 | G9: 180 | H9: 122 | I9: =E9+G9 -> 246 | J9: =(E9-F9)+(G9-H9) -> 101
A10: RO5190 | B10: 45676 | C10: =TEXT(B10,"mmm") -> Jan | D10: Internal | E10: 104 | F10: 41 | G10: 161 | H10: 127 | I10: =E10+G10 -> 265 | J10: =(E10-F10)+(G10-H10) -> 97
A11: RO5104 | B11: 45684 | C11: =TEXT(B11,"mmm") -> Jan | D11: Customer Pay | E11: 236 | F11: 81 | G11: 215 | H11: 128 | I11: =E11+G11 -> 451 | J11: =(E11-F11)+(G11-H11) -> 242
A12: RO5082 | B12: 45685 | C12: =TEXT(B12,"mmm") -> Jan | D12: Warranty | E12: 199 | F12: 73 | G12: 228 | H12: 151 | I12: =E12+G12 -> 427 | J12: =(E12-F12)+(G12-H12) -> 203
A13: RO5119 | B13: 45685 | C13: =TEXT(B13,"mmm") -> Jan | D13: Customer Pay | E13: 217 | F13: 93 | G13: 424 | H13: 281 | I13: =E13+G13 -> 641 | J13: =(E13-F13)+(G13-H13) -> 267
A14: RO5071 | B14: 45690 | C14: =TEXT(B14,"mmm") -> Feb | D14: Customer Pay | E14: 734 | F14: 307 | G14: 518 | H14: 289 | I14: =E14+G14 -> 1252 | J14: =(E14-F14)+(G14-H14) -> 656
A15: RO5015 | B15: 45691 | C15: =TEXT(B15,"mmm") -> Feb | D15: Customer Pay | E15: 842 | F15: 345 | G15: 183 | H15: 115 | I15: =E15+G15 -> 1025 | J15: =(E15-F15)+(G15-H15) -> 565
... A203: RO5174 | B203: 46019 | C203: =TEXT(B203,"mmm") -> Dec | D203: Customer Pay | E203: 838 | F203: 256 | G203: 499 | H203: 291 | I203: =E203+G203 -> 1337 | J203: =(E203-F203)+(G203-H203) -> 790
A206: REVENUE BY TYPE × MONTH (formula-driven pivot)
A207: Month | B207: Customer Pay Count | C207: Warranty Count | D207: Internal Count | E207: Customer Pay Revenue | F207: Warranty Revenue | G207: Internal Revenue | H207: Total Revenue | I207: Total Gross
A208: Jan | B208: =COUNTIFS($C$4:$C$203,A208,$D$4:$D$203,"Customer Pay") -> 6 | C208: =COUNTIFS($C$4:$C$203,A208,$D$4:$D$203,"Warranty") -> 3 | D208: =COUNTIFS($C$4:$C$203,A208,$D$4:$D$203,"Internal") -> 1 | E208: =SUMIFS($I$4:$I$203,$C$4:$C$203,A208,$D$4:$D$203,"Customer Pay") -> 4562 | F208: =SUMIFS($I$4:$I$203,$C$4:$C$203,A208,$D$4:$D$203,"Warranty") -> 1417 | G208: =SUMIFS($I$4:$I$203,$C$4:$C$203,A208,$D$4:$D$203,"Internal") -> 265 | H208: =SUMIFS($I$4:$I$203,$C$4:$C$203,A208) -> 6244 | I208: =SUMIFS($J$4:$J$203,$C$4:$C$203,A208) -> 3090
A209: Feb | B209: =COUNTIFS($C$4:$C$203,A209,$D$4:$D$203,"Customer Pay") -> 10 | C209: =COUNTIFS($C$4:$C$203,A209,$D$4:$D$203,"Warranty") -> 7 | D209: =COUNTIFS($C$4:$C$203,A209,$D$4:$D$203,"Internal") -> 4 | E209: =SUMIFS($I$4:$I$203,$C$4:$C$203,A209,$D$4:$D$203,"Customer Pay") -> 9825 | F209: =SUMIFS($I$4:$I$203,$C$4:$C$203,A209,$D$4:$D$203,"Warranty") -> 3703 | G209: =SUMIFS($I$4:$I$203,$C$4:$C$203,A209,$D$4:$D$203,"Internal") -> 1208 | H209: =SUMIFS($I$4:$I$203,$C$4:$C$203,A209) -> 14736 | I209: =SUMIFS($J$4:$J$203,$C$4:$C$203,A209) -> 7516
A210: Mar | B210: =COUNTIFS($C$4:$C$203,A210,$D$4:$D$203,"Customer Pay") -> 5 | C210: =COUNTIFS($C$4:$C$203,A210,$D$4:$D$203,"Warranty") -> 5 | D210: =COUNTIFS($C$4:$C$203,A210,$D$4:$D$203,"Internal") -> 1 | E210: =SUMIFS($I$4:$I$203,$C$4:$C$203,A210,$D$4:$D$203,"Customer Pay") -> 4053 | F210: =SUMIFS($I$4:$I$203,$C$4:$C$203,A210,$D$4:$D$203,"Warranty") -> 2469 | G210: =SUMIFS($I$4:$I$203,$C$4:$C$203,A210,$D$4:$D$203,"Internal") -> 300 | H210: =SUMIFS($I$4:$I$203,$C$4:$C$203,A210) -> 6822 | I210: =SUMIFS($J$4:$J$203,$C$4:$C$203,A210) -> 3491
A211: Apr | B211: =COUNTIFS($C$4:$C$203,A211,$D$4:$D$203,"Customer Pay") -> 7 | C211: =COUNTIFS($C$4:$C$203,A211,$D$4:$D$203,"Warranty") -> 8 | D211: =COUNTIFS($C$4:$C$203,A211,$D$4:$D$203,"Internal") -> 2 | E211: =SUMIFS($I$4:$I$203,$C$4:$C$203,A211,$D$4:$D$203,"Customer Pay") -> 5385 | F211: =SUMIFS($I$4:$I$203,$C$4:$C$203,A211,$D$4:$D$203,"Warranty") -> 4096 | G211: =SUMIFS($I$4:$I$203,$C$4:$C$203,A211,$D$4:$D$203,"Internal") -> 637 | H211: =SUMIFS($I$4:$I$203,$C$4:$C$203,A211) -> 10118 | I211: =SUMIFS($J$4:$J$203,$C$4:$C$203,A211) -> 4997
A212: May | B212: =COUNTIFS($C$4:$C$203,A212,$D$4:$D$203,"Customer Pay") -> 9 | C212: =COUNTIFS($C$4:$C$203,A212,$D$4:$D$203,"Warranty") -> 4 | D212: =COUNTIFS($C$4:$C$203,A212,$D$4:$D$203,"Internal") -> 0 | E212: =SUMIFS($I$4:$I$203,$C$4:$C$203,A212,$D$4:$D$203,"Customer Pay") -> 7864 | F212: =SUMIFS($I$4:$I$203,$C$4:$C$203,A212,$D$4:$D$203,"Warranty") -> 1556 | G212: =SUMIFS($I$4:$I$203,$C$4:$C$203,A212,$D$4:$D$203,"Internal") -> 0 | H212: =SUMIFS($I$4:$I$203,$C$4:$C$203,A212) -> 9420 | I212: =SUMIFS($J$4:$J$203,$C$4:$C$203,A212) -> 5087
A213: Jun | B213: =COUNTIFS($C$4:$C$203,A213,$D$4:$D$203,"Customer Pay") -> 15 | C213: =COUNTIFS($C$4:$C$203,A213,$D$4:$D$203,"Warranty") -> 3 | D213: =COUNTIFS($C$4:$C$203,A213,$D$4:$D$203,"Internal") -> 3 | E213: =SUMIFS($I$4:$I$203,$C$4:$C$203,A213,$D$4:$D$203,"Customer Pay") -> 12850 | F213: =SUMIFS($I$4:$I$203,$C$4:$C$203,A213,$D$4:$D$203,"Warranty") -> 1807 | G213: =SUMIFS($I$4:$I$203,$C$4:$C$203,A213,$D$4:$D$203,"Internal") -> 729 | H213: =SUMIFS($I$4:$I$203,$C$4:$C$203,A213) -> 15386 | I213: =SUMIFS($J$4:$J$203,$C$4:$C$203,A213) -> 7779
A214: Jul | B214: =COUNTIFS($C$4:$C$203,A214,$D$4:$D$203,"Customer Pay") -> 8 | C214: =COUNTIFS($C$4:$C$203,A214,$D$4:$D$203,"Warranty") -> 7 | D214: =COUNTIFS($C$4:$C$203,A214,$D$4:$D$203,"Internal") -> 2 | E214: =SUMIFS($I$4:$I$203,$C$4:$C$203,A214,$D$4:$D$203,"Customer Pay") -> 7617 | F214: =SUMIFS($I$4:$I$203,$C$4:$C$203,A214,$D$4:$D$203,"Warranty") -> 4029 | G214: =SUMIFS($I$4:$I$203,$C$4:$C$203,A214,$D$4:$D$203,"Internal") -> 524 | H214: =SUMIFS($I$4:$I$203,$C$4:$C$203,A214) -> 12170 | I214: =SUMIFS($J$4:$J$203,$C$4:$C$203,A214) -> 5980
A215: Aug | B215: =COUNTIFS($C$4:$C$203,A215,$D$4:$D$203,"Customer Pay") -> 6 | C215: =COUNTIFS($C$4:$C$203,A215,$D$4:$D$203,"Warranty") -> 1 | D215: =COUNTIFS($C$4:$C$203,A215,$D$4:$D$203,"Internal") -> 4 | E215: =SUMIFS($I$4:$I$203,$C$4:$C$203,A215,$D$4:$D$203,"Customer Pay") -> 5611 | F215: =SUMIFS($I$4:$I$203,$C$4:$C$203,A215,$D$4:$D$203,"Warranty") -> 250 | G215: =SUMIFS($I$4:$I$203,$C$4:$C$203,A215,$D$4:$D$203,"Internal") -> 1304 | H215: =SUMIFS($I$4:$I$203,$C$4:$C$203,A215) -> 7165 | I215: =SUMIFS($J$4:$J$203,$C$4:$C$203,A215) -> 3677
A216: Sep | B216: =COUNTIFS($C$4:$C$203,A216,$D$4:$D$203,"Customer Pay") -> 10 | C216: =COUNTIFS($C$4:$C$203,A216,$D$4:$D$203,"Warranty") -> 9 | D216: =COUNTIFS($C$4:$C$203,A216,$D$4:$D$203,"Internal") -> 2 | E216: =SUMIFS($I$4:$I$203,$C$4:$C$203,A216,$D$4:$D$203,"Customer Pay") -> 8765 | F216: =SUMIFS($I$4:$I$203,$C$4:$C$203,A216,$D$4:$D$203,"Warranty") -> 4763 | G216: =SUMIFS($I$4:$I$203,$C$4:$C$203,A216,$D$4:$D$203,"Internal") -> 856 | H216: =SUMIFS($I$4:$I$203,$C$4:$C$203,A216) -> 14384 | I216: =SUMIFS($J$4:$J$203,$C$4:$C$203,A216) -> 7264
A217: Oct | B217: =COUNTIFS($C$4:$C$203,A217,$D$4:$D$203,"Customer Pay") -> 8 | C217: =COUNTIFS($C$4:$C$203,A217,$D$4:$D$203,"Warranty") -> 9 | D217: =COUNTIFS($C$4:$C$203,A217,$D$4:$D$203,"Internal") -> 3 | E217: =SUMIFS($I$4:$I$203,$C$4:$C$203,A217,$D$4:$D$203,"Customer Pay") -> 6019 | F217: =SUMIFS($I$4:$I$203,$C$4:$C$203,A217,$D$4:$D$203,"Warranty") -> 4715 | G217: =SUMIFS($I$4:$I$203,$C$4:$C$203,A217,$D$4:$D$203,"Internal") -> 804 | H217: =SUMIFS($I$4:$I$203,$C$4:$C$203,A217) -> 11538 | I217: =SUMIFS($J$4:$J$203,$C$4:$C$203,A217) -> 5711
A218: Nov | B218: =COUNTIFS($C$4:$C$203,A218,$D$4:$D$203,"Customer Pay") -> 11 | C218: =COUNTIFS($C$4:$C$203,A218,$D$4:$D$203,"Warranty") -> 6 | D218: =COUNTIFS($C$4:$C$203,A218,$D$4:$D$203,"Internal") -> 0 | E218: =SUMIFS($I$4:$I$203,$C$4:$C$203,A218,$D$4:$D$203,"Customer Pay") -> 8869 | F218: =SUMIFS($I$4:$I$203,$C$4:$C$203,A218,$D$4:$D$203,"Warranty") -> 3843 | G218: =SUMIFS($I$4:$I$203,$C$4:$C$203,A218,$D$4:$D$203,"Internal") -> 0 | H218: =SUMIFS($I$4:$I$203,$C$4:$C$203,A218) -> 12712 | I218: =SUMIFS($J$4:$J$203,$C$4:$C$203,A218) -> 6363
A219: Dec | B219: =COUNTIFS($C$4:$C$203,A219,$D$4:$D$203,"Customer Pay") -> 15 | C219: =COUNTIFS($C$4:$C$203,A219,$D$4:$D$203,"Warranty") -> 4 | D219: =COUNTIFS($C$4:$C$203,A219,$D$4:$D$203,"Internal") -> 2 | E219: =SUMIFS($I$4:$I$203,$C$4:$C$203,A219,$D$4:$D$203,"Customer Pay") -> 13042 | F219: =SUMIFS($I$4:$I$203,$C$4:$C$203,A219,$D$4:$D$203,"Warranty") -> 2071 | G219: =SUMIFS($I$4:$I$203,$C$4:$C$203,A219,$D$4:$D$203,"Internal") -> 543 | H219: =SUMIFS($I$4:$I$203,$C$4:$C$203,A219) -> 15656 | I219: =SUMIFS($J$4:$J$203,$C$4:$C$203,A219) -> 7786
A220: TOTAL | B220: =SUM(B208:B219) -> 110 | C220: =SUM(C208:C219) -> 66 | D220: =SUM(D208:D219) -> 24 | E220: =SUM(E208:E219) -> 94462 | F220: =SUM(F208:F219) -> 34719 | G220: =SUM(G208:G219) -> 7170 | H220: =SUM(H208:H219) -> 136351 | I220: =SUM(I208:I219) -> 68741
A223: SERVICE ABSORPTION (circular ref ↔ P&L Overhead)
A224: Service Gross | B224: =SUMPRODUCT(SV_LaborRev-SV_LaborCost) -> 48018
A225: Parts Gross | B225: =SUMPRODUCT(SV_PartsRev-SV_PartsCost) -> 20723
A226: Total Dealership Overhead | B226: ='P&L Summary'!$N$25 -> 310333.33
A227: SERVICE ABSORPTION RATE | B227: =IFERROR((B224+B225)/B226,0) -> 0.22150698
A228: Target | B228: =ServiceAbsorptionTarget -> 0.8
A229: Variance vs Target | B229: =B227-B228 -> -0.57849302

Sheet Assumptions
A1: ASSUMPTIONS & DRIVERS
A3: Assumption | B3: Value | C3: Effective Date | D3: Notes | E3: Status
A4: FloorPlanRate | B4: 0.058 | C4: 44927 | D4: Used vehicle floor plan APR (STALE) | E4: =IF(TODAY()-C4>$B$15,"STALE — review","Current") -> STALE — review
A5: IncentiveRate_Toyota | B5: 0.021 | C5: 45658 | D5: OEM incentive % of invoice | E5: =IF(TODAY()-C5>$B$15,"STALE — review","Current") -> STALE — review
A6: IncentiveRate_Honda | B6: 0.018 | C6: 45658 | D6: OEM incentive % of invoice | E6: =IF(TODAY()-C6>$B$15,"STALE — review","Current") -> STALE — review
A7: IncentiveRate_Ford | B7: 0.025 | C7: 45658 | D7: OEM incentive % of invoice | E7: =IF(TODAY()-C7>$B$15,"STALE — review","Current") -> STALE — review
A8: FI_PVR_Target | B8: 1600 | C8: 45444 | D8: F&I per vehicle retailed target | E8: =IF(TODAY()-C8>$B$15,"STALE — review","Current") -> STALE — review
A9: ServiceAbsorptionTarget | B9: 0.8 | C9: 44986 | D9: Fixed ops coverage target (STALE) | E9: =IF(TODAY()-C9>$B$15,"STALE — review","Current") -> STALE — review
A10: TaxRate | B10: 0.21 | C10: 45292 | D10: Effective corporate tax rate | E10: =IF(TODAY()-C10>$B$15,"STALE — review","Current") -> STALE — review
A11: HoldbackRate | B11: 0.025 | C11: 45078 | D11: Mfr holdback on invoice (STALE) | E11: =IF(TODAY()-C11>$B$15,"STALE — review","Current") -> STALE — review
A12: ReconCostCap | B12: 2500 | C12: 45689 | D12: Max recon cost before escalation | E12: =IF(TODAY()-C12>$B$15,"STALE — review","Current") -> STALE — review
A13: OverheadAllocationMethod | B13: revenue-weighted | C13: 45292 | D13: Method for OH alloc | E13: =IF(TODAY()-C13>$B$15,"STALE — review","Current") -> STALE — review
A14: VarianceThreshold | B14: 0.1 | C14: 45658 | D14: CF threshold for red highlight | E14: =IF(TODAY()-C14>$B$15,"STALE — review","Current") -> STALE — review
